/data/home/zzk/workspace/zzk/Benchmark/projects/polyrnn-pp/src/PolygonModel.py
/data/home/zzk/workspace/zzk/Benchmark/projects/polyrnn-pp/src/vis_predictions.py
/data/home/zzk/workspace/zzk/Benchmark/projects/polyrnn-pp/src/__init__.py
/data/home/zzk/workspace/zzk/Benchmark/projects/polyrnn-pp/src/inference.py
/data/home/zzk/workspace/zzk/Benchmark/projects/polyrnn-pp/src/poly_utils.py
/data/home/zzk/workspace/zzk/Benchmark/projects/polyrnn-pp/src/EvalNet.py
/data/home/zzk/workspace/zzk/Benchmark/projects/polyrnn-pp/src/GGNNPolyModel.py
/data/home/zzk/workspace/zzk/Benchmark/projects/polyrnn-pp/src/utils.py
Not in virtualenv
cuDNN not found!
bazel not found
......................................................................................
Current library: numpy (v1.14.2)
Knowledge base: {'library': {'keras': [('2.2.4', 'yes', ['53617072'])]}, 'hardware': {}, 'programming_language': {'python': [('3', 'yes', ['57734033'])]}, 'operating_system': {}, 'tool': {}}
--------------------------------DC ISSUE-----------------------------------------
ERROR: Local numpy (v1.14.2) may not be compatible with python (v3.6) (1)
Recommand StackOverflow Posts: 
https://stackoverflow.com/questions/57734033
-----------------------------------END-------------------------------------------
......................................................................................
Current library: scipy (v1.0.1)
Knowledge base: {'library': {}, 'hardware': {}, 'programming_language': {'python': [('3', 'yes', ['57734033'])]}, 'operating_system': {}, 'tool': {}}
--------------------------------DC ISSUE-----------------------------------------
ERROR: Local scipy (v1.0.1) may not be compatible with python (v3.6) (1)
Recommand StackOverflow Posts: 
https://stackoverflow.com/questions/57734033
-----------------------------------END-------------------------------------------
......................................................................................
Current library: tensorflow (v1.3.0)
Knowledge base: {'library': {}, 'hardware': {'cudnn': [('64', 'yes', ['43566341', '46080926', '45779371']), ('7', 'no', ['58382360'])], 'cuda': [('9', 'no', ['46689778', '58382360', '47008832']), ('8', 'yes', ['46189616', '46778006', '46940714', '47008832'])]}, 'programming_language': {}, 'operating_system': {}, 'tool': {'bazel': [('0.13.1', 'yes', ['50518061']), ('0.5.1', 'yes', ['50518061'])]}}
--------------------------------DC ISSUE-----------------------------------------
cudnn is not installed in local, the recommended version is ['64']
-----------------------------------END-------------------------------------------
--------------------------------DC ISSUE-----------------------------------------
ERROR: Local tensorflow (v1.3.0) is not compatible with cuda (v11.2) (0)
-----------------------------------END-------------------------------------------
++++++++++++++++++++++++++++API CHECK++++++++++++++++++++++++++++
......................................................................................
Current API: np.where
Knowledge base: {'library': {'pandas': [('1.1.2', 'yes', ['64273727'])]}, 'hardware': {}, 'programming_language': {'python': [('0', 'no', ['9516304']), ('3', 'no', ['9516304'])]}, 'operating_system': {}, 'tool': {}}
......................................................................................
Current API: tensorflow.contrib
Knowledge base: {'library': {'tensorflow': [('2', 'no', ['55524156'])]}, 'hardware': {}, 'programming_language': {}, 'operating_system': {}, 'tool': {}}
......................................................................................
Current API: np.zeros
Knowledge base: {'library': {'numpy': [('3.95', 'yes', ['44866614'])]}, 'hardware': {}, 'programming_language': {}, 'operating_system': {}, 'tool': {}}
......................................................................................
Current API: os.path.isdir
Knowledge base: {'library': {}, 'hardware': {}, 'programming_language': {'python': [('3', 'yes', ['44661513'])]}, 'operating_system': {}, 'tool': {}}
--------------------------------DC ISSUE-----------------------------------------
ERROR: os.path.isdir may not be compatible with python (v3.6) (1)
Recommand StackOverflow Posts: 
https://stackoverflow.com/questions/44661513
-----------------------------------END-------------------------------------------
......................................................................................
Current API: os.path
Knowledge base: {'library': {}, 'hardware': {}, 'programming_language': {'python': [('3.5', 'yes', ['37095733']), ('2.7', 'yes', ['3430395']), ('3', 'yes', ['3430395', '4119176', '44661513']), ('3.4', 'no', ['45223014', '51149057'])]}, 'operating_system': {}, 'tool': {}}
--------------------------------DC ISSUE-----------------------------------------
ERROR: Local os.path is not compatible with python (v3.6) (3)
-----------------------------------END-------------------------------------------
......................................................................................
Current API: tf.zeros
Knowledge base: {'library': {'tensorflow': [('2', 'yes', ['59585408']), ('1.5', 'yes', ['59585408'])]}, 'hardware': {}, 'programming_language': {}, 'operating_system': {}, 'tool': {}}
......................................................................................
Current API: np.sum
Knowledge base: {'library': {}, 'hardware': {}, 'programming_language': {'python': [('4.5ms', 'yes', ['66886682'])]}, 'operating_system': {}, 'tool': {}}
......................................................................................
Current API: glob.glob
Knowledge base: {'library': {}, 'hardware': {}, 'programming_language': {'python': [('3', 'yes', ['44661513', '48393588']), ('3.5', 'no', ['37173091', '44661513'])]}, 'operating_system': {}, 'tool': {}}
--------------------------------DC ISSUE-----------------------------------------
ERROR: Local glob.glob is not compatible with python (v3.6) (3)
-----------------------------------END-------------------------------------------
--------------------------------DC ISSUE-----------------------------------------
ERROR: Local glob.glob may not be compatible with python (v3.6) (4)
-----------------------------------END-------------------------------------------
......................................................................................
Current API: np.array
Knowledge base: {'library': {'numpy': [('0.325', 'yes', ['67695754']), ('8.99849401', 'yes', ['46085625']), ('21.87729639', 'yes', ['46085625'])]}, 'hardware': {}, 'programming_language': {'python': [('3', 'no', ['3877247'])]}, 'operating_system': {}, 'tool': {}}
--------------------------------DC ISSUE-----------------------------------------
ERROR: Local np.array is not compatible with python (v3.6) (2)
Recommand StackOverflow Posts: 
https://stackoverflow.com/questions/3877247
-----------------------------------END-------------------------------------------
......................................................................................
Current API: json.load
Knowledge base: {'library': {}, 'hardware': {}, 'programming_language': {'python': [('3.6', 'yes', ['35245605'])]}, 'operating_system': {}, 'tool': {}}
--------------------------------DC ISSUE-----------------------------------------
ERROR: json.load may not be compatible with python (v3.6) (1)
Recommand StackOverflow Posts: 
https://stackoverflow.com/questions/35245605
-----------------------------------END-------------------------------------------
......................................................................................
Current API: saver.restore
Knowledge base: {'library': {'tensorflow': [('0.12', 'no', ['41495299'])]}, 'hardware': {}, 'programming_language': {}, 'operating_system': {}, 'tool': {}}
......................................................................................
Current API: sess.run
Knowledge base: {'library': {'tensorflow': [('1', 'yes', ['64942713'])]}, 'hardware': {}, 'programming_language': {}, 'operating_system': {}, 'tool': {}}
......................................................................................
Current API: tf.logging
Knowledge base: {'library': {'tensorflow': [('2', 'no', ['55318851'])]}, 'hardware': {}, 'programming_language': {}, 'operating_system': {}, 'tool': {}}
......................................................................................
Current API: matplotlib.pyplot
Knowledge base: {'library': {}, 'hardware': {}, 'programming_language': {'python': [('3', 'yes', ['52500781']), ('2.7.5', 'yes', ['42448458'])]}, 'operating_system': {}, 'tool': {}}
......................................................................................
Current API: collections.namedtuple
Knowledge base: {'library': {}, 'hardware': {}, 'programming_language': {'python': [('2.6', 'yes', ['1389232', '2218845', '2512690', '3358084', '8413368'])]}, 'operating_system': {}, 'tool': {}}
--------------------------------DC ISSUE-----------------------------------------
ERROR: collections.namedtuple may not be compatible with python (v3.6) (1)
Recommand StackOverflow Posts: 
https://stackoverflow.com/questions/1389232
https://stackoverflow.com/questions/2218845
https://stackoverflow.com/questions/2512690
https://stackoverflow.com/questions/3358084
https://stackoverflow.com/questions/8413368
-----------------------------------END-------------------------------------------
......................................................................................
Current API: tf.placeholder
Knowledge base: {'library': {'tensorflow': [('2', 'no', ['60316058']), ('1.3', 'yes', ['47051723'])]}, 'hardware': {}, 'programming_language': {}, 'operating_system': {}, 'tool': {}}
......................................................................................
Current API: os.path.join
Knowledge base: {'library': {'tensorflow': [('8', 'no', ['6766266'])]}, 'hardware': {}, 'programming_language': {'python': [('9', 'no', ['47748008']), ('3', 'no', ['6766266']), ('3.4', 'no', ['2909998'])]}, 'operating_system': {}, 'tool': {}}
......................................................................................
Current API: matplotlib.use
Knowledge base: {'library': {}, 'hardware': {}, 'programming_language': {'python': [('3', 'yes', ['52500781'])]}, 'operating_system': {}, 'tool': {}}
--------------------------------DC ISSUE-----------------------------------------
ERROR: matplotlib.use may not be compatible with python (v3.6) (1)
Recommand StackOverflow Posts: 
https://stackoverflow.com/questions/52500781
-----------------------------------END-------------------------------------------
